<?xml version="1.0" ?>
<!-- =================================================================================== -->
<!-- |    This document was autogenerated by xacro from dual_sia5d.xacro               | -->
<!-- |    EDITING THIS FILE BY HAND IS NOT RECOMMENDED                                 | -->
<!-- =================================================================================== -->
<robot name="dual_sia5d" xmlns:xacro="http://ros.org/wiki/xacro">
  <material name="blue">
    <color rgba="0 0 0.8 1"/>
  </material>
  <!--degrees to radians-->
  <link name="primo_base_link">
    <visual>
      <origin rpy="0 0 0" xyz="0 0 0"/>
      <geometry>
        <mesh filename="package://motoman_sia5d_support/meshes/sia5d/visual/base.dae"/>
      </geometry>
    </visual>
    <collision>
      <origin rpy="0 0 0" xyz="0 0 0"/>
      <geometry>
        <mesh filename="package://motoman_sia5d_support/meshes/sia5d/collision/base.dae"/>
      </geometry>
    </collision>
  </link>
  <link name="primo_link_s">
    <visual>
      <origin rpy="0 0 0" xyz="0 0 0"/>
      <geometry>
        <mesh filename="package://motoman_sia5d_support/meshes/sia5d/visual/link_s.dae"/>
      </geometry>
    </visual>
    <collision>
      <origin rpy="0 0 0" xyz="0 0 0"/>
      <geometry>
        <mesh filename="package://motoman_sia5d_support/meshes/sia5d/collision/link_s.dae"/>
      </geometry>
    </collision>
  </link>
  <joint name="primo_joint_s" type="revolute">
    <origin rpy="0 0 0" xyz="0 0 0.31"/>
    <!--r=${90*deg}-->
    <parent link="primo_base_link"/>
    <child link="primo_link_s"/>
    <axis xyz="0 0 1"/>
    <limit effort="0" lower="-3.14159274" upper="3.14159274" velocity="3.4906586"/>
  </joint>
  <link name="primo_link_l">
    <visual>
      <origin rpy="0 0 0" xyz="0 0 0"/>
      <geometry>
        <mesh filename="package://motoman_sia5d_support/meshes/sia5d/visual/link_l.dae"/>
      </geometry>
    </visual>
    <collision>
      <origin rpy="0 0 0" xyz="0 0 0"/>
      <geometry>
        <mesh filename="package://motoman_sia5d_support/meshes/sia5d/collision/link_l.dae"/>
      </geometry>
    </collision>
  </link>
  <joint name="primo_joint_l" type="revolute">
    <origin rpy="0 0 0" xyz="0 0 0"/>
    <parent link="primo_link_s"/>
    <child link="primo_link_l"/>
    <axis xyz="0 1 0"/>
    <limit effort="0" lower="-1.91986223" upper="1.91986223" velocity="3.4906586"/>
  </joint>
  <link name="primo_link_e">
    <visual>
      <origin rpy="0 0 0" xyz="0 0 0"/>
      <geometry>
        <mesh filename="package://motoman_sia5d_support/meshes/sia5d/visual/link_e.dae"/>
      </geometry>
    </visual>
    <collision>
      <origin rpy="0 0 0" xyz="0 0 0"/>
      <geometry>
        <mesh filename="package://motoman_sia5d_support/meshes/sia5d/collision/link_e.dae"/>
      </geometry>
    </collision>
  </link>
  <joint name="primo_joint_e" type="revolute">
    <origin rpy="0 0 0" xyz="0 0 0.27"/>
    <parent link="primo_link_l"/>
    <child link="primo_link_e"/>
    <axis xyz="0 0 1"/>
    <limit effort="0" lower="-2.96705981" upper="2.96705981" velocity="3.4906586"/>
  </joint>
  <link name="primo_link_u">
    <visual>
      <origin rpy="0 0 0" xyz="0 0 0"/>
      <geometry>
        <mesh filename="package://motoman_sia5d_support/meshes/sia5d/visual/link_u.dae"/>
      </geometry>
    </visual>
    <collision>
      <origin rpy="0 0 0" xyz="0 0 0"/>
      <geometry>
        <mesh filename="package://motoman_sia5d_support/meshes/sia5d/collision/link_u.dae"/>
      </geometry>
    </collision>
  </link>
  <joint name="primo_joint_u" type="revolute">
    <origin rpy="0 0 0" xyz="0.085 0 0"/>
    <parent link="primo_link_e"/>
    <child link="primo_link_u"/>
    <axis xyz="0 1 0"/>
    <limit effort="0" lower="-1.57079637" upper="2.007128695" velocity="3.4906586"/>
  </joint>
  <link name="primo_link_r">
    <visual>
      <origin rpy="0 0 0" xyz="0 0 0"/>
      <geometry>
        <mesh filename="package://motoman_sia5d_support/meshes/sia5d/visual/link_r.dae"/>
      </geometry>
    </visual>
    <collision>
      <origin rpy="0 0 0" xyz="0 0 0"/>
      <geometry>
        <mesh filename="package://motoman_sia5d_support/meshes/sia5d/collision/link_r.dae"/>
      </geometry>
    </collision>
  </link>
  <joint name="primo_joint_r" type="revolute">
    <origin rpy="0 0 0" xyz="0.27 0 0.06"/>
    <parent link="primo_link_u"/>
    <child link="primo_link_r"/>
    <axis xyz="-1 0 0"/>
    <limit effort="0" lower="-1.57079637" upper="1.57079637" velocity="3.4906586"/>
  </joint>
  <link name="primo_link_b">
    <visual>
      <origin rpy="0 0 0" xyz="0 0 0"/>
      <geometry>
        <mesh filename="package://motoman_sia5d_support/meshes/sia5d/visual/link_b.dae"/>
      </geometry>
    </visual>
    <collision>
      <origin rpy="0 0 0" xyz="0 0 0"/>
      <geometry>
        <mesh filename="package://motoman_sia5d_support/meshes/sia5d/collision/link_b.dae"/>
      </geometry>
    </collision>
  </link>
  <joint name="primo_joint_b" type="revolute">
    <origin rpy="0 0 0" xyz="0 0 0"/>
    <parent link="primo_link_r"/>
    <child link="primo_link_b"/>
    <axis xyz="0 1 0"/>
    <limit effort="0" lower="-1.91986223" upper="1.91986223" velocity="4.01425739"/>
  </joint>
  <link name="primo_link_t">
    <visual>
      <origin rpy="0 0 0" xyz="0 0 0"/>
      <geometry>
        <mesh filename="package://motoman_sia5d_support/meshes/sia5d/visual/link_t.dae"/>
      </geometry>
    </visual>
    <collision>
      <origin rpy="0 0 0" xyz="0 0 0"/>
      <geometry>
        <mesh filename="package://motoman_sia5d_support/meshes/sia5d/collision/link_t.dae"/>
      </geometry>
    </collision>
  </link>
  <joint name="primo_joint_t" type="revolute">
    <origin rpy="0 0 0" xyz="0.134 0 0"/>
    <parent link="primo_link_b"/>
    <child link="primo_link_t"/>
    <axis xyz="-1 0 0"/>
    <limit effort="0" lower="-1.57079637" upper="1.57079637" velocity="6.10865255"/>
  </joint>
  <link name="primo_tool0"/>
  <joint name="primo_link_t-tool0" type="fixed">
    <origin rpy="-1.57079637 -1.57079637 -1.57079637" xyz="0.011 0 0"/>
    <parent link="primo_link_t"/>
    <child link="primo_tool0"/>
  </joint>
  <!-- ROS base_link (via link_l) to Motoman Robot (not Base) Frame transform -->
  <link name="primo_base"/>
  <joint name="primo_link_l-base" type="fixed">
    <origin rpy="0 0 0" xyz="0 0 0"/>
    <parent link="primo_link_l"/>
    <child link="primo_base"/>
  </joint>
  <!--degrees to radians-->
  <link name="secunda_base_link">
    <visual>
      <origin rpy="0 0 0" xyz="0 0 0"/>
      <geometry>
        <mesh filename="package://motoman_sia5d_support/meshes/sia5d/visual/base.dae"/>
      </geometry>
    </visual>
    <collision>
      <origin rpy="0 0 0" xyz="0 0 0"/>
      <geometry>
        <mesh filename="package://motoman_sia5d_support/meshes/sia5d/collision/base.dae"/>
      </geometry>
    </collision>
  </link>
  <link name="secunda_link_s">
    <visual>
      <origin rpy="0 0 0" xyz="0 0 0"/>
      <geometry>
        <mesh filename="package://motoman_sia5d_support/meshes/sia5d/visual/link_s.dae"/>
      </geometry>
    </visual>
    <collision>
      <origin rpy="0 0 0" xyz="0 0 0"/>
      <geometry>
        <mesh filename="package://motoman_sia5d_support/meshes/sia5d/collision/link_s.dae"/>
      </geometry>
    </collision>
  </link>
  <joint name="secunda_joint_s" type="revolute">
    <origin rpy="0 0 0" xyz="0 0 0.31"/>
    <!--r=${90*deg}-->
    <parent link="secunda_base_link"/>
    <child link="secunda_link_s"/>
    <axis xyz="0 0 1"/>
    <limit effort="0" lower="-3.14159274" upper="3.14159274" velocity="3.4906586"/>
  </joint>
  <link name="secunda_link_l">
    <visual>
      <origin rpy="0 0 0" xyz="0 0 0"/>
      <geometry>
        <mesh filename="package://motoman_sia5d_support/meshes/sia5d/visual/link_l.dae"/>
      </geometry>
    </visual>
    <collision>
      <origin rpy="0 0 0" xyz="0 0 0"/>
      <geometry>
        <mesh filename="package://motoman_sia5d_support/meshes/sia5d/collision/link_l.dae"/>
      </geometry>
    </collision>
  </link>
  <joint name="secunda_joint_l" type="revolute">
    <origin rpy="0 0 0" xyz="0 0 0"/>
    <parent link="secunda_link_s"/>
    <child link="secunda_link_l"/>
    <axis xyz="0 1 0"/>
    <limit effort="0" lower="-1.91986223" upper="1.91986223" velocity="3.4906586"/>
  </joint>
  <link name="secunda_link_e">
    <visual>
      <origin rpy="0 0 0" xyz="0 0 0"/>
      <geometry>
        <mesh filename="package://motoman_sia5d_support/meshes/sia5d/visual/link_e.dae"/>
      </geometry>
    </visual>
    <collision>
      <origin rpy="0 0 0" xyz="0 0 0"/>
      <geometry>
        <mesh filename="package://motoman_sia5d_support/meshes/sia5d/collision/link_e.dae"/>
      </geometry>
    </collision>
  </link>
  <joint name="secunda_joint_e" type="revolute">
    <origin rpy="0 0 0" xyz="0 0 0.27"/>
    <parent link="secunda_link_l"/>
    <child link="secunda_link_e"/>
    <axis xyz="0 0 1"/>
    <limit effort="0" lower="-2.96705981" upper="2.96705981" velocity="3.4906586"/>
  </joint>
  <link name="secunda_link_u">
    <visual>
      <origin rpy="0 0 0" xyz="0 0 0"/>
      <geometry>
        <mesh filename="package://motoman_sia5d_support/meshes/sia5d/visual/link_u.dae"/>
      </geometry>
    </visual>
    <collision>
      <origin rpy="0 0 0" xyz="0 0 0"/>
      <geometry>
        <mesh filename="package://motoman_sia5d_support/meshes/sia5d/collision/link_u.dae"/>
      </geometry>
    </collision>
  </link>
  <joint name="secunda_joint_u" type="revolute">
    <origin rpy="0 0 0" xyz="0.085 0 0"/>
    <parent link="secunda_link_e"/>
    <child link="secunda_link_u"/>
    <axis xyz="0 1 0"/>
    <limit effort="0" lower="-1.57079637" upper="2.007128695" velocity="3.4906586"/>
  </joint>
  <link name="secunda_link_r">
    <visual>
      <origin rpy="0 0 0" xyz="0 0 0"/>
      <geometry>
        <mesh filename="package://motoman_sia5d_support/meshes/sia5d/visual/link_r.dae"/>
      </geometry>
    </visual>
    <collision>
      <origin rpy="0 0 0" xyz="0 0 0"/>
      <geometry>
        <mesh filename="package://motoman_sia5d_support/meshes/sia5d/collision/link_r.dae"/>
      </geometry>
    </collision>
  </link>
  <joint name="secunda_joint_r" type="revolute">
    <origin rpy="0 0 0" xyz="0.27 0 0.06"/>
    <parent link="secunda_link_u"/>
    <child link="secunda_link_r"/>
    <axis xyz="-1 0 0"/>
    <limit effort="0" lower="-1.57079637" upper="1.57079637" velocity="3.4906586"/>
  </joint>
  <link name="secunda_link_b">
    <visual>
      <origin rpy="0 0 0" xyz="0 0 0"/>
      <geometry>
        <mesh filename="package://motoman_sia5d_support/meshes/sia5d/visual/link_b.dae"/>
      </geometry>
    </visual>
    <collision>
      <origin rpy="0 0 0" xyz="0 0 0"/>
      <geometry>
        <mesh filename="package://motoman_sia5d_support/meshes/sia5d/collision/link_b.dae"/>
      </geometry>
    </collision>
  </link>
  <joint name="secunda_joint_b" type="revolute">
    <origin rpy="0 0 0" xyz="0 0 0"/>
    <parent link="secunda_link_r"/>
    <child link="secunda_link_b"/>
    <axis xyz="0 1 0"/>
    <limit effort="0" lower="-1.91986223" upper="1.91986223" velocity="4.01425739"/>
  </joint>
  <link name="secunda_link_t">
    <visual>
      <origin rpy="0 0 0" xyz="0 0 0"/>
      <geometry>
        <mesh filename="package://motoman_sia5d_support/meshes/sia5d/visual/link_t.dae"/>
      </geometry>
    </visual>
    <collision>
      <origin rpy="0 0 0" xyz="0 0 0"/>
      <geometry>
        <mesh filename="package://motoman_sia5d_support/meshes/sia5d/collision/link_t.dae"/>
      </geometry>
    </collision>
  </link>
  <joint name="secunda_joint_t" type="revolute">
    <origin rpy="0 0 0" xyz="0.134 0 0"/>
    <parent link="secunda_link_b"/>
    <child link="secunda_link_t"/>
    <axis xyz="-1 0 0"/>
    <limit effort="0" lower="-1.57079637" upper="1.57079637" velocity="6.10865255"/>
  </joint>
  <link name="secunda_tool0"/>
  <joint name="secunda_link_t-tool0" type="fixed">
    <origin rpy="-1.57079637 -1.57079637 -1.57079637" xyz="0.011 0 0"/>
    <parent link="secunda_link_t"/>
    <child link="secunda_tool0"/>
  </joint>
  <!-- ROS base_link (via link_l) to Motoman Robot (not Base) Frame transform -->
  <link name="secunda_base"/>
  <joint name="secunda_link_l-base" type="fixed">
    <origin rpy="0 0 0" xyz="0 0 0"/>
    <parent link="secunda_link_l"/>
    <child link="secunda_base"/>
  </joint>
  <link name="base_link">
    <visual>
      <geometry>
        <box size="1.5 1 0.2"/>
      </geometry>
      <material name="blue"/>
    </visual>
  </link>
  <joint name="primo_base_joint" type="fixed">
    <parent link="base_link"/>
    <child link="primo_base_link"/>
    <origin rpy="0 0 3.141592654" xyz="-0.5 0 0.1"/>
  </joint>
  <joint name="secunda_base_joint" type="fixed">
    <parent link="base_link"/>
    <child link="secunda_base_link"/>
    <origin rpy="0 0 3.141592654" xyz="0.5 0 0.1"/>
  </joint>
</robot>

